# 2021-10-10

## 2021-10-08 문제점 #1 계속

```bash
Assertion failed: n == 0 && "iterator out of bounds", file C:\Temp\boost_1_77_0\boost_1_77_0\boost\asio\buffers_iterator.hpp, line 434
```

여전히 클라이언트에서는 이러한 에러를 발생시킨다.

첫번째 의심점

- 여러 스레드에서 호출하는 하나의 핸들러, tcp_connection 내부에선 async_read_until, write_some 핸들러들은 람다로 실행된다. 이들을 io_context::strand로 묶어서 스레드로부터 안전하도록 만들었다. 이와 관련된 좋은 답변이 달린 [스택오버플로우](https://stackoverflow.com/questions/12794107/why-do-i-need-strand-per-connection-when-using-boostasio/12801042#12801042) 질문
- 서버에선 두개의 io_context.run()을 호출받은 스레드들의 순서를 보장하기 위해서이다.
- 서버와 클라이언트 모두 tcp_connection을 사용하므로 다중 스레드 실행 시 다양한 예상할 수 없는 문제들로부터 안전하게 만들었다. (어떠한 문제인지는 확실하진 않지만 다른 글들을 참고했을 때 같은 io_context를 공유할 때 핸들러의 실행이 겹치게 되는 것을 예방하기 위해서다)

두번째 의심점

- 클라이언트에서 호출될 때 에러가 발생하는 것을 보면 클라이언트에서 문제가 있는 듯 보였다.
- 에러의 내용은 buffers_iterator라는 헤더파일 내에서 반복자가 범위를 넘어나는 에러다.

<img src="https://user-images.githubusercontent.com/45554623/136685964-bd473b5b-a54b-4fde-aa7f-bef126567963.png">

- 문제의 원인을 찾았다. client main는 사용자의 입력에 따라 특정한 메시지를 서버에 전송한다. 서버에서는 그에 대한 응답을 한다. 드래그 해놓은 부분은 서버의 응답의 문자열이 겹쳐져서 발생한 부분이다. 
- 하지만 과연 저렇게 응답을 받았다고해서 abort() 호출 에러 즉, 스레드가 강제로 종료되어버리는 에러가 뜨는 직접적인 이유일까? 
- 다음은 tcp_connection에서 수신 메시지를 처리하는 과정이다.
  1. 소켓으로부터 읽어낸 데이터를 '\n'문자를 만날 때까지 streambuf에 입력한다.
  2. async_read_until의 완료 핸들러는 두개의 매개변수가 있다. 1. 오류 2. 읽은 데이터 크기, 읽은 데이터 크기만큼 문자열을 만들고 streambuf의 현위치(current position)을 consume(bytes)를 통해 뒤로 당긴다. 이는 다음부터 읽어낼 데이터 위치를 바꿔주는 것이다.
  3. (2)에서 만들어낸 문자열을 수신 덱에 넣고 다시 비동기 읽기를 시작한다. (1)로 회귀

- 계속된 디버깅을 해봤는데 같은 상황을 다시 만드는게 영 쉬운 일이 아니다.
- async_read_until 부분이 문제인거 같은데 구체적으로 무엇이 문제가 되는 것인지 모르겠다. 동시성 프로그래밍의 어려움을 뼈져리게 느끼고 있다. 🤐